Workbook

Sheet README
A1: The Conditioning Atlas
A2: Priming windows, doses, and persistence of induced environmental memory in marine invertebrates
A4: 109 experiments extracted from 105 papers. One row per experiment: a paper running two stressors or two species appears more than once, with the same DOI and an a/b suffix on the Study ID.
A6: WHAT THIS IS FOR
A7: The lab framework states that the application program for environmental conditioning is to 'identify the windows, identify the doses, and characterize how long the induced memory persists relative to commercial production timescales.' Nobody had that in tabular form. This is that table.
A9: SHEETS
A10: Atlas — the data. Filterable. Direction and Decay are colour-coded (green = beneficial/persisted, red = worsened/decayed, grey = not tested).
A11: Coverage gaps — live COUNTIFS over the Atlas sheet, plus the structural gaps the atlas exposes. Add rows to Atlas and these recalculate.
A12: Data dictionary — what every column means and its allowed values.
A13: Screened out — the 131 papers that were checked and rejected, with the reason. Kept so the screening is auditable and not repeated.
A15: HOW TO READ THE PRIORITY COLUMNS
A16: Persistence (days) is days from the END of conditioning to the assessment. A 0 means offspring were spawned straight into the challenge. A '~' means the value was derived from the paper's own reported numbers rather than stated outright.
... A25: Built 2026-09-17.

Sheet Atlas
A1: Study ID | B1: DOI | C1: PMID | D1: Year | E1: Species | F1: Taxon | G1: Stressor | H1: Stressor category | I1: Conditioning stage | J1: Dose (treatment vs control) | K1: Conditioning duration | L1: Generations | M1: Transmission route | N1: Later challenge | O1: Persistence (days) | P1: Multiple timepoints? | Q1: Decay | R1: Phenotypic readouts | S1: Direction of effect | T1: Effect magnitude | U1: Molecular layers | V1: Molecular-phenotype concordance | W1: Applied framing | X1: Replication | Y1: Evidence source | Z1: Editorial notice | AA1: Notes | AB1: Cluster
A2: Parker_2012 | B2: 10.1111/j.1365-2486.2011.02520.x | C2: not reported | D2: 2012 | E2: Saccostrea glomerata | F2: Bivalve | G2: reduced pH (elevated pCO2) | H2: pH/OA | I2: Broodstock/adult | J2: 856 uatm pCO2 (pH_NBS 7.89-7.90) vs ambient 380-385 uatm (pH_NBS 8.19-8.20) | K2: reproductive conditioning from gametogenesis to gravid stage; exact length not obtainable from accessible text (paywalled) | L2: F0-F1 | M2: Both parents | N2: elevated pCO2 856 uatm through larval development | O2: ~0 | P2: Yes | Q2: Not tested | R2: larval shell growth; rate of development; larval survival; adult standard metabolic rate | S2: Improved | T2: larvae from pCO2-exposed adults were larger (~10% larger per Venkataraman et al. 2019 re-quote) and developed faster at elevated pCO2, with similar survival; selectively bred larvae more resilient than wild; adult SMR increased under elevated pCO2 | U2: None | V2: Not evaluated | W2: Aquaculture | X2: wild and selectively bred (industry fast-growth) lines; tank replication not obtainable from accessible text | Y2: Abstract + citations | Z2: None found | AA2: Foundational S. glomerata transgenerational OA study that all later Parker/Ross work builds on; both a wild and a selectively bred line were used and the bred line was more OA-tolerant, confounding non-genetic priming with standing genetic variation; paywalled so duration and replication could not be extracted | AB2: Bivalve: temperature & pH
A3: Parker_2015 | B3: 10.1371/journal.pone.0132276 | C3: 26147612 | D3: 2015 | E3: Saccostrea glomerata | F3: Bivalve | G3: reduced pH (elevated pCO2) | H3: pH/OA | I3: Multiple | J3: 856 uatm pCO2 (pH_T 7.90, Omega_arag 1.95) vs ambient 385 uatm (pH_T 8.20, Omega_arag 3.43); TA 2329-2334 umol/kg, 24 C, salinity 34.5 | K3: F0 adults 5 weeks to gravid stage; F1 larvae 19-21 d to eyed stage; F1 adults re-exposed 5 weeks; F2 larvae 19 d; F2 spat 6 d | L3: F0-F1-F2 | M3: Both parents | N3: elevated pCO2 856 uatm re-applied to F1 adults (5 w) and to F2 larvae (19 d) and F2 spat (6 d) | O3: ~426 | P3: Yes | Q3: Persisted | R3: F1 adult extracellular pH (pHe) and standard metabolic rate; F2 larval survival, % eyed, % abnormality, shell length; F2 spat shell growth and heart rate | S3: Improved | T3: F1 pCO2-history adults dropped only -0.30 pHe units at 856 uatm vs -0.43 in controls (MS=0.02, F=25.26, df=1, p<0.01); 73% of F2 pCO2-history larvae reached eyed stage at 856 uatm vs 50% of controls (MS=1408.33, F=10.56, p<0.05); F2 abnormality lower at elevated pCO2 (F=6.00, p<0.05); F2 spat grew faster and had higher heart rate at both pCO2 levels; whole-organism SMR increase did NOT differ between lines (F=132.96 for CO2, no line effect) | U3: None | V3: Not evaluated | W3: Aquaculture | X3: 3 replicate 40 L tubs per treatment fed from 3 x 750 L header tanks; 50 adults per tub; gametes pooled from >=10 males and >=10 females per line; 3 replicate 200 L larval tanks per line; spat 3 x 30 individuals per line; 6 adults per line x treatment for pHe/SMR | Y3: Full text | Z3: None found | AA3: The single most important persistence result in bivalve conditioning: benefit survived 14 months of common-garden ambient CO2 in the field between F1 settlement and F1 adult re-exposure. Trade-off flagged by the authors: F2 pCO2-line larvae were SMALLER at 1 d post-fertilization (reduced maternal provisioning) yet outperformed controls by day 19, and the faster growth/heart rate may reflect selection for high metabolic rate, which narrows thermal windows and raises food demand. Group spawning (10x10 pooled) means natural selection on ~46% larval mortality cannot be separated from non-genetic inheritance | AB3: Bivalve: temperature & pH
A4: Parker_2017 | B4: 10.1098/rsbl.2016.0798 | C4: 28202683 | D4: 2017 | E4: Saccostrea glomerata | F4: Bivalve | G4: reduced pH (elevated pCO2) parental priming; larvae then challenged with pCO2 crossed with temperature, salinity and food | H4: pH/OA | I4: Broodstock/adult | J4: parents 856 uatm vs 392 uatm pCO2; larval challenge factorially with 28 C vs 24 C, salinity 25 vs 35, half vs full algal diet | K4: 8 weeks, from the beginning of gametogenesis until gravid stage | L4: F0-F1 | M4: Both parents | N4: elevated pCO2 856 uatm alone and factorially combined with 28 C, salinity 25 and half food ration; 15 d larval rearing | O4: ~0 | P4: Yes | Q4: Not tested | R4: larval shell length (15 d); % development to umbonate stage (9 d); % survival (through 15 d); larval standard metabolic rate (15 d) | S4: Mixed | T4: under elevated pCO2 alone larvae from pCO2-exposed parents were 8% larger (143.5 +/- s.e. 1.5 um vs 132.5 +/- s.e. 3.0 um) and developed faster; BUT total survival was lower (0.24 vs 0.30; F(1,28)=5.73, p<0.05) and there was 0% survival of pCO2-parent larvae by day 13 in the pCO2+temperature treatment and by day 15 in pCO2+temperature+salinity+food; larvae from pCO2-exposed parents had higher SMR | U4: None | V4: Not evaluated | W4: Aquaculture | X4: 3 replicate parental tanks per exposure (6 experimental units); 3 replicate 20 L fertilization buckets per treatment per parental exposure; unbalanced ANOVA because all replicates died in some cells | Y4: Full text | Z4: None found | AA4: The canonical MALADAPTIVE case: the same parental OA priming that helps under OA alone is lethal under co-stressors, because the mechanism (elevated larval SMR) accelerates energy depletion. Egg size and total lipid did not differ between parental treatments, so the effect is not maternal provisioning. Authors note parents were primed with pCO2 only, not with the full stressor suite the larvae met, and that a longer parental exposure might have given a different result | AB4: Bivalve: temperature & pH
A5: Parker_2021 | B5: 10.1242/jeb.239269 | C5: not reported | D5: 2021 | E5: Saccostrea glomerata | F5: Bivalve | G5: reduced pH (elevated pCO2) crossed with tidal habitat (intertidal emersion vs subtidal immersion) | H5: pH/OA | I5: Broodstock/adult | J5: elevated 1000 uatm vs ambient 400 uatm pCO2, crossed with intertidal (simulated daily emersion, metabolic hypercapnia) vs subtidal (constant immersion) | K5: 5 weeks of combined tidal x pCO2 reproductive conditioning to gravid stage | L5: F0-F1 | M5: Both parents | N5: larvae reared at ambient or elevated pCO2 for 48 h | O5: ~2 | P5: No | Q5: Not tested | R5: larval shell size; % abnormality; % development; larval metabolic rate | S5: Mixed | T5: elevated pCO2 reduced larval size by 9% in offspring of subtidal parents but only 4% in offspring of intertidal parents (habitat x CO2 interaction), so intertidal-conditioned larvae at elevated pCO2 matched subtidal-conditioned larvae at ambient pCO2; however subtidal parents exposed to elevated pCO2 transmitted a beneficial carryover effect while intertidal parents exposed to elevated pCO2 transmitted NO improvement; parent habitat had no effect on % abnormality | U5: None | V5: Not evaluated | W5: Aquaculture | X5: n = 3 replicates per tidal x pCO2 treatment | Y5: Full text | Z5: None found | AA5: Natural conditioning contrast (tidal habitat) crossed with experimental OA in the laboratory. Key pattern: intertidal provenance buys higher baseline tolerance but COSTS the capacity for beneficial transgenerational plasticity, i.e. existing tolerance and inducible tolerance trade off. Implies TGP measured on subtidal broodstock will overestimate the benefit available across a species range. Only a 48 h post-fertilization assessment, so no persistence window | AB5: Bivalve: temperature & pH
A6: Parker_2025 | B6: 10.1016/j.marenvres.2025.107540 | C6: 41015001 | D6: 2025 | E6: Saccostrea glomerata | F6: Bivalve | G6: reduced pH (elevated pCO2) | H6: pH/OA | I6: Broodstock/adult | J6: elevated 1000 uatm vs ambient 410 uatm pCO2 | K6: 9 weeks of reproductive conditioning | L6: F0-F1 | M6: Both parents | N6: D-veliger larvae reared 48 h at ambient (410 uatm) or elevated (1000 uatm) pCO2 | O6: ~2 | P6: No | Q6: Not tested | R6: % development; % abnormality; shell length; larval respiration rate | S6: Mixed | T6: quoted: significant variability in TGP responses among families to elevated pCO2, with positive, negative, and neutral responses in larval offspring across the four families; per-family magnitudes not given in the abstract | U6: None | V6: Not evaluated | W6: Aquaculture | X6: 4 genetically distinct families, within-family crosses | Y6: Abstract only | Z6: None found | AA6: Directly tests the assumption behind every other TGP row here: the species-average response hides families whose offspring are HARMED by parental priming. Any hatchery application therefore needs family-level screening. Paywalled, so doses beyond the two pCO2 levels, exact replication and effect sizes are unavailable | AB6: Bivalve: temperature & pH
A7: Filippini_2025 | B7: 10.1016/j.marpolbul.2025.118896 | C7: 41202725 | D7: 2025 | E7: Saccostrea glomerata | F7: Bivalve | G7: elevated temperature (ocean warming) | H7: Temperature | I7: Broodstock/adult | J7: 28 C (warm) vs 24 C (control) | K7: ~8 weeks during reproductive conditioning | L7: F0-F1 | M7: Both parents | N7: 48 h larval exposure across a thermal gradient of 24.3-36.0 C; LT50 determined | O7: ~2 | P7: No | Q7: Not tested | R7: % development; % abnormality; shell size; larval LT50 | S7: Mixed | T7: larvae from warm (28 C) parents had greater development and lower abnormality but were SMALLER at higher temperatures than larvae from 24 C parents; parental warming raised larval LT50 by approximately 2.0 C in one of the two families | U7: None | V7: Not evaluated | W7: Aquaculture | X7: 2 genetically distinct families, within-family crosses | Y7: Abstract only | Z7: None found | AA7: One of very few bivalve TGP studies using warming rather than OA as the conditioning stressor, and one of the only ones reporting a thermal-tolerance effect size (LT50 +2.0 C). Benefit is family-specific and traded off against larval size. Journal DOI is not yet in the Scite index (only the SSRN preprint 10.2139/ssrn.5269282 resolves there); DOI confirmed via PubMed and no editorial notices found on either record | AB7: Bivalve: temperature & pH
A8: Goncalves_2016 | B8: 10.1111/mec.13808 | C8: not reported | D8: 2016 | E8: Saccostrea glomerata | F8: Bivalve | G8: reduced pH (elevated pCO2) | H8: pH/OA | I8: Multiple | J8: F2 challenge 625 uatm pCO2 (pH 7.87) vs ambient 387 uatm (pH 8.03); transgenerational acclimation applied over three consecutive generations | K8: elevated pCO2 across three consecutive generations, then a 1 week F2 juvenile exposure before transcriptional analysis | L8: F0-F1-F2 | M8: Both parents | N8: elevated pCO2 625 uatm for 1 week (F2 juveniles) | O8: ~0 | P8: No | Q8: Not tested | R8: targeted stress-response gene expression (ecSOD, catalase, peroxiredoxin 6, metabolism and cytoskeleton genes); no organismal performance endpoint | S8: Not assessable | T8: transgenerationally acclimated B2-line oysters had HIGHER expression of all differentially expressed genes (fold change >=1.4) than non-acclimated B2 under pCO2 stress, whereas pCO2-acclimated wild-type oysters showed widespread DOWNregulation under the same stress; transgenerational exposure altered both basal and inducible expression | U8: Targeted qPCR | V8: Discordant | W8: Aquaculture | X8: 2 genetically distinct breeding lines (B2 disease-resistant fast-growing selected line vs wild type) | Y8: Full text | Z8: None found | AA8: The molecular counterpart to Parker's phenotypic TGP in the same species, and it shows the direction of transcriptional acclimation FLIPS with genetic background (up in the selected line, down in wild type). There is therefore no single molecular signature of successful priming in this species. No performance readout, so molecular-phenotypic concordance cannot be tested within the paper | AB8: Bivalve: temperature & pH
A9: Gibbs_2021 | B9: 10.1093/icesjms/fsab071 | C9: not reported | D9: 2021 | E9: Saccostrea glomerata; Magallana gigas (Crassostrea gigas) | F9: Bivalve | G9: reduced pH (elevated pCO2) and elevated temperature, orthogonal | H9: Multiple | I9: Broodstock/adult | J9: orthogonal ambient vs elevated pCO2 and ambient vs elevated temperature; numeric levels not stated in the abstract | K9: 8 weeks of adult exposure, then 9 d larval rearing | L9: F0-F1 | M9: Both parents | N9: larvae reared 9 days under ambient or elevated pCO2 | O9: ~0 | P9: No | Q9: Not tested | R9: egg lipidome; larval morphology; larval lipidome | S9: Mixed | T9: quoted: parental exposure to warming and elevated pCO2 led to limited beneficial transgenerational responses for eggs and larvae of both species; S. glomerata larvae were more sensitive than C. gigas; both species had some capacity for TGP; authors conclude TGP may not be a panacea and does not act equally across species | U9: None | V9: Not evaluated | W9: Aquaculture | X9: not reported | Y9: Abstract only | Z9: None found | AA9: Important as an explicit negative/limited result from the same group that produced the strongest positive TGP findings, and one of the few designs conditioning parents with warming AND OA together. Doses, durations beyond the 8 w exposure, replication and effect sizes are behind a paywall; lipidomics is the only mechanistic layer and it is not paired with a molecular-epigenetic readout | AB9: Bivalve: temperature & pH
A10: Pereira_2020 | B10: 10.1371/journal.pone.0228527 | C10: 32275675 | D10: 2020 | E10: Ostrea angasi; Saccostrea glomerata | F10: Bivalve | G10: acute sublethal heat shock (stress inoculation) followed by chronic habitat warming | H10: Temperature | I10: Broodstock/adult | J10: heat shock 26 C for 18 h then 28 C for 6 h (24 h total, +6 C then +2 C from 20 C) vs 20 C control; challenge = power-station thermal outfall, mean 24.56 +/- 4.59 C, daily max 32.81 +/- 0.39 C vs ambient site mean 20.06 +/- 3.85 C | K10: 24 h heat shock; 12 h ramp-down; ~1 week at ambient 20 C in the estuary; then ~7 months (May-Dec) field deployment | L10: F0 | M10: Within-generation only | N10: ~7 months of continuous elevated field temperature at two power-station thermal outfalls | O10: ~220 | P10: No | Q10: Not tested | R10: shell growth (mm/d); condition index; standard metabolic rate; total lipid and lipid class profile (TAG, phospholipids); survival | S10: Mixed | T10: O. angasi survival at elevated temperature was 80% in heat-shocked vs 53% in non-shocked oysters (and 100% vs 90% at ambient); PERMANOVA heat shock x temperature F=16.61, p<=0.04. BUT heat-shocked O. angasi grew LESS at ambient temperature (0.08 +/- 0.01 vs 0.10 +/- 0.01 mm/d), and shell growth at elevated temperature was ~10-fold lower than at ambient regardless of priming. S. glomerata shell growth was unaffected by temperature or heat shock; condition index fell with temperature in both species irrespective of priming. Elevated temperature lowered O. angasi TAG | U10: None | V10: Not evaluated | W10: Both | X10: 5 baskets recovered (2 ambient, 3 elevated); 10 oysters per species per treatment per basket; 120 oysters at elevated and 80 at ambient temperature; SMR n=9-11 per species/treatment/basket; lipids n=5 (n=3 and n=2 for two heat-shock groups at one site) | Y10: Full text | Z10: None found | AA10: One of the few studies that quantifies the COST of priming: heat shock reduced ambient-temperature growth in O. angasi while raising survival under warming. Authors' own conclusion is that early stress inoculation does not enhance resilience and may not be a useful strategy for O. angasi restoration. They flag the 24 h shock as possibly too short for HSP accumulation or epigenetic shifts. Uses a thermal outfall as a real-world warming proxy, which also means the challenge was uncontrolled and multi-stressor | AB10: Bivalve: temperature & pH
A11: Gurr_2020 | B11: 10.1093/conphys/coaa024 | C11: 32274068 | D11: 2020 | E11: Panopea generosa | F11: Bivalve | G11: reduced pH (elevated pCO2, aragonite undersaturation) | H11: pH/OA | I11: Juvenile | J11: initial exposure 2345 +/- 20 uatm pCO2, pH_T 7.31, Omega_arag 0.41 vs ambient 608 +/- 11 uatm, pH_T 7.8, Omega_arag 1.35; secondary exposure 2551 +/- 42 uatm, pH_T 7.27, Omega_arag 0.39 vs 506 +/- 5 uatm, pH_T 7.93, Omega_arag 1.60; ambient common garden 557 +/- 17 uatm, pH 7.9, Omega 1.46 | K11: initial 10 d exposure; 14 d ambient common garden; secondary 6 d reciprocal exposure; then 157 d ambient common garden | L11: F0 | M11: Within-generation only | N11: reciprocal 6 d elevated pCO2 (2551 uatm) at days 24-30, then 157 d ambient common garden | O11: 157 | P11: Yes | Q11: Strengthened | R11: respiration rate (ug O2/h/mm shell length); shell length; survival | S11: Improved | T11: initial 10 d elevated pCO2 depressed respiration 25% (CO2 F=7.512, p=0.007) with no effect on shell length; respiration difference from initial treatment was still detectable after 14 d in ambient common garden (Welch t=2.673, p=0.015); shell length was reduced ~4% by initial and ~3.2% by secondary elevated pCO2 during the second encounter (F=15.821, p<0.001 and F=9.917, p=0.002); after 157 d in ambient common garden, initially-primed clams were 5.8% LARGER (F=5.228, p=0.023) and secondarily-exposed clams had 52.4% HIGHER respiration (F=13.008, p=0.001); all animals survived the 30 d exposure, 1-4 deaths per tray over grow-out | U11: None | V11: Not evaluated | W11: Aquaculture | X11: 4 conical header tanks and 4 heath trays per treatment; 80 clams per tray (n=640 total); 2 trays per initial x secondary treatment combination in the reciprocal phase; respirometry 3 vials of 10 individuals per tray during exposures, 1 individual per vial at 157 d; 3 blank vials per tray | Y11: Full text | Z11: None found | AA11: Best-quantified persistence window in the bivalve literature (157 d common garden) and a rare STRENGTHENING rather than decay: the effect on shell length was absent at 14 d, negative at 30 d, and positive at 187 d. Authors are candid that a 5.8% size gain is unlikely to repay the feed needed to sustain 52% higher respiration, and that the shell response may partly reflect the second exposure being 0.04 pH units more severe than the first plus seasonal warming. Metabolic depression (not elevation) was the primed phenotype, opposite to Parker's S. glomerata | AB11: Bivalve: temperature & pH
A12: Gurr_2022 | B12: 10.1111/mec.16644 | C12: 35947503 | D12: 2022 | E12: Panopea generosa | F12: Bivalve | G12: reduced pH (elevated pCO2) | H12: pH/OA | I12: Juvenile | J12: priming 2870 uatm pCO2 (pre-exposed) vs 921 uatm (naive); second exposure 754 (ambient) / 2750 (moderate) / 4940 uatm (severe); third exposure 967 vs 3030 uatm | K12: 110 d priming acclimation; 7 d second exposure; 7 d ambient recovery; 7 d third exposure | L12: F0 | M12: Within-generation only | N12: 7 d at moderately (2750 uatm) and severely (4940 uatm) elevated pCO2, a 7 d ambient recovery, then a third 7 d exposure at 3030 uatm | O12: 0 | P12: Yes | Q12: Persisted | R12: TagSeq whole-transcriptome gene expression, interpreted against companion phenotypes (shell growth, tissue biomass, total antioxidant capacity) from the same animals | S12: Improved | T12: pre-exposed geoducks frontloaded gene sets for stress and apoptosis/innate immune response, homeostasis, protein degradation and transcriptional modifiers, and remained responsive to later encounters (mitochondrial recycling and immune defence under elevated pCO2; energy metabolism and biosynthesis during ambient recovery); naive clams were enriched for fatty-acid degradation and glutathione components, interpreted as depletion of endogenous fuel; companion phenotype was reduced total antioxidant capacity plus increased shell growth and tissue biomass in primed clams | U12: Transcriptome (RNA-seq) | V12: Concordant | W12: Aquaculture | X12: N=8 per treatment at day 0 (end of priming); N=6 at day 7 and day 14 (one cell N=5); N=3-6 at day 21 | Y12: Abstract + citations | Z12: None found | AA12: Longest conditioning dose in this table (110 d) and the only bivalve study that samples the transcriptome at the same timepoints as the phenotype, giving a genuine concordance test. Mechanism proposed is gene frontloading plus sustained histone-methyltransferase expression as the memory substrate. The 4940 uatm arm is important because it tests whether priming still helps at doses beyond the priming intensity | AB12: Bivalve: temperature & pH
... A110: Thor_2015 | B110: 10.1111/gcb.12815 | C110: 25430823 | D110: 2015 | E110: Pseudocalanus acuspes | F110: Crustacean | G110: elevated pCO2 | H110: pH/OA | I110: Multiple | J110: pCO2 900 uatm and 1550 uatm vs 400 uatm control | K110: two full generations at the treatment pCO2 | L110: F0-F1 | M110: Route not resolved | N110: reciprocal transplant of second-generation adults between pCO2 levels | O110: 0 | P110: Yes | Q110: Persisted | R110: fecundity (egg production rate); respiration/metabolic rate | S110: Improved | T110: second-generation adults showed a 29% decrease in fecundity at 900 uatm vs 400 uatm accompanied by a 10% increase in metabolic rate; reciprocal transplants showed that WITHOUT transgenerational effects fecundity would have fallen by as much as 67% at 1550 uatm; transgenerational effects held the loss at the 900-uatm level and removed the metabolic-stress signal, with respiration rates lower than at 900 uatm; the effect was fully reversible on transplant, i.e. phenotypic plasticity rather than fixation | U110: Transcriptome (RNA-seq) | V110: Discordant (the molecular companion study on the same two-generation experiment, De Wit et al. 2015, 10.1111/eva.12335, found genes involved in RNA transcription strongly DOWN-regulated in high-pCO2 lineages EVEN AFTER transplant back to control pCO2, plus 1513 of ~747,000 SNPs with consistent replicate frequency shifts in RNA transcription, ribosomal function, ion transport and oxidative phosphorylation - so the fecundity phenotype reversed but the transcriptome did not) | W110: None | X110: 6 laboratory populations (2 replicate populations per pCO2 level) | Y110: Abstract + citations | Z110: None found | AA110: One of very few studies to QUANTIFY how much of an apparent OA effect is masked by transgenerational plasticity (67% predicted loss vs ~29% realised). Critical caveat from the companion paper: over two generations, plasticity and selection cannot be separated (estimated mortality >50% per generation), and the molecular state did NOT return to baseline even though the phenotype did. | AB110: Hypoxia / salinity / pollutant / other taxa

Sheet Coverage gaps
A1: Conditioning Atlas — coverage and gaps | B1: =COUNTA(Atlas!A2:A110) | C1: rows in Atlas
A2: All counts are live COUNTIFS/COUNTA formulas over Atlas!A2:AB110. Edit or add rows in Atlas and these update.
A4: Taxonomic coverage
A5: Category | B5: Studies | C5: % of atlas
A6: Bivalve | B6: =COUNTIFS(Atlas!F$2:F$110,A6) | C6: =IFERROR(B6/$B$12,0)
A7: Coral/cnidarian | B7: =COUNTIFS(Atlas!F$2:F$110,A7) | C7: =IFERROR(B7/$B$12,0)
A8: Crustacean | B8: =COUNTIFS(Atlas!F$2:F$110,A8) | C8: =IFERROR(B8/$B$12,0)
A9: Echinoderm | B9: =COUNTIFS(Atlas!F$2:F$110,A9) | C9: =IFERROR(B9/$B$12,0)
A10: Polychaete/other | B10: =COUNTIFS(Atlas!F$2:F$110,A10) | C10: =IFERROR(B10/$B$12,0)
A11: Gastropod | B11: =COUNTIFS(Atlas!F$2:F$110,A11) | C11: =IFERROR(B11/$B$12,0)
A12: TOTAL | B12: =SUM(B6:B11)
A14: Stressor coverage
A15: Category | B15: Studies | C15: % of atlas
A16: Temperature | B16: =COUNTIFS(Atlas!H$2:H$110,A16) | C16: =IFERROR(B16/$B$23,0)
A17: Pathogen/immune | B17: =COUNTIFS(Atlas!H$2:H$110,A17) | C17: =IFERROR(B17/$B$23,0)
A18: pH/OA | B18: =COUNTIFS(Atlas!H$2:H$110,A18) | C18: =IFERROR(B18/$B$23,0)
A19: Multiple | B19: =COUNTIFS(Atlas!H$2:H$110,A19) | C19: =IFERROR(B19/$B$23,0)
A20: Pollutant | B20: =COUNTIFS(Atlas!H$2:H$110,A20) | C20: =IFERROR(B20/$B$23,0)
A21: Hypoxia | B21: =COUNTIFS(Atlas!H$2:H$110,A21) | C21: =IFERROR(B21/$B$23,0)
A22: Salinity | B22: =COUNTIFS(Atlas!H$2:H$110,A22) | C22: =IFERROR(B22/$B$23,0)
A23: TOTAL | B23: =SUM(B16:B22)
A25: Conditioning window
A26: Category | B26: Studies | C26: % of atlas
A27: Broodstock/adult | B27: =COUNTIFS(Atlas!I$2:I$110,A27) | C27: =IFERROR(B27/$B$32,0)
A28: Juvenile | B28: =COUNTIFS(Atlas!I$2:I$110,A28) | C28: =IFERROR(B28/$B$32,0)
A29: Multiple | B29: =COUNTIFS(Atlas!I$2:I$110,A29) | C29: =IFERROR(B29/$B$32,0)
A30: Embryo | B30: =COUNTIFS(Atlas!I$2:I$110,A30) | C30: =IFERROR(B30/$B$32,0)
A31: Larva | B31: =COUNTIFS(Atlas!I$2:I$110,A31) | C31: =IFERROR(B31/$B$32,0)
A32: TOTAL | B32: =SUM(B27:B31)
A34: Direction of effect
A35: Category | B35: Studies | C35: % of atlas
A36: Improved | B36: =COUNTIFS(Atlas!S$2:S$110,A36) | C36: =IFERROR(B36/$B$41,0)
A37: Mixed | B37: =COUNTIFS(Atlas!S$2:S$110,A37) | C37: =IFERROR(B37/$B$41,0)
A38: Worsened | B38: =COUNTIFS(Atlas!S$2:S$110,A38) | C38: =IFERROR(B38/$B$41,0)
A39: No effect | B39: =COUNTIFS(Atlas!S$2:S$110,A39) | C39: =IFERROR(B39/$B$41,0)
A40: Not assessable | B40: =COUNTIFS(Atlas!S$2:S$110,A40) | C40: =IFERROR(B40/$B$41,0)
A41: TOTAL | B41: =SUM(B36:B40)
A43: Was decay of the induced state tested?
A44: Category | B44: Studies | C44: % of atlas
A45: Persisted | B45: =COUNTIFS(Atlas!Q$2:Q$110,A45) | C45: =IFERROR(B45/$B$49,0)
...

Sheet Data dictionary
A1: Column | B1: Definition | C1: Allowed values / format
A2: Study ID | B2: First author surname + year; a/b suffix distinguishes separate experiments from one paper. | C2: Lastname_Year
A3: DOI | B3: Bare DOI. Prefix with https://doi.org/ to open. | C3: text
A4: PMID | B4: PubMed ID where indexed. | C4: integer or 'not reported'
A5: Year | B5: Publication year. | C5: integer
A6: Species | B6: Full Latin binomial(s) of the conditioned organism. | C6: text
A7: Taxon | B7: Broad taxonomic group. | C7: Bivalve | Coral/cnidarian | Gastropod | Echinoderm | Crustacean | Polychaete/other | Multiple
A8: Stressor | B8: The specific stressor used in the CONDITIONING exposure. | C8: text
A9: Stressor category | B9: Binned stressor for filtering. | C9: Temperature | pH/OA | Hypoxia | Salinity | Pollutant | Pathogen/immune | Multiple
A10: Conditioning stage | B10: Life stage the priming exposure was applied to — the 'programming window'. | C10: Broodstock/adult | Gamete | Embryo | Larva | Juvenile | Multiple
A11: Dose (treatment vs control) | B11: Quantitative intensity of the conditioning exposure, always paired with the control value. | C11: text with units
A12: Conditioning duration | B12: How long the conditioning exposure lasted; cycling regimes described. | C12: text with units
... A29: Cluster | B29: Which extraction sweep the row came from. Retained for provenance. | C29: text

Sheet Screened out
A1: DOI / identifier | B1: Title | C1: Reason for exclusion | D1: Sweep
A2: 10.7717/peerj.18273 | B2: Coral recruits demonstrate thermal resilience. | C2: Coral (Scleractinia), not a bivalve - outside this scope assignment | D2: Bivalve: temperature & pH
A3: 10.1126/sciadv.aaw9530 | B3: How colonial animals evolve. | C3: Not a bivalve and not a primary conditioning experiment (evolutionary synthesis on colonial animals) | D3: Bivalve: temperature & pH
A4: 10.1002/ece3.70570 | B4: Fertile Hybrids Could Aid Coral Adaptation. | C4: Coral, not a bivalve; hybridisation rather than a priming exposure | D4: Bivalve: temperature & pH
A5: 10.1098/rstb.2023.0065 | B5: Cross-talk and mutual shaping between the immune system and the microbiota during an oyster's life. | C5: Review article, not a primary empirical study (fails inclusion criterion 4) | D5: Bivalve: temperature & pH
A6: 10.1016/bs.mcb.2018.11.010 | B6: The painted sea urchin, Lytechinus pictus, as a genetically-enabled developmental model. | C6: Echinoderm methods/resource paper, not a bivalve and not a conditioning experiment | D6: Bivalve: temperature & pH
A7: 10.1038/s41380-023-02331-5 | B7: Maternal educational attainment in pregnancy and epigenome-wide DNA methylation changes in the offspring from birth until adolescence. | C7: Human study - not a marine invertebrate | D7: Bivalve: temperature & pH
A8: 10.1016/j.scitotenv.2024.172616 | B8: Transgenerational acclimation to acidified seawater and gene expression patterns in a sea urchin. | C8: Echinoderm (sea urchin), not a bivalve - outside this scope assignment | D8: Bivalve: temperature & pH
A9: 10.7717/peerj.15519 | B9: Coral affected by stony coral tissue loss disease can produce viable offspring. | C9: Coral, not a bivalve; disease rather than temperature/pH conditioning | D9: Bivalve: temperature & pH
A10: 10.1038/s41598-020-70605-x | B10: Environmentally-induced parental or developmental conditioning influences coral offspring ecological performance. | C10: Coral, not a bivalve - outside this scope assignment | D10: Bivalve: temperature & pH
A11: 10.1016/j.marpolbul.2023.115060 | B11: Response of resistant larvae of the coral Acropora tenuis to future thermal stress. | C11: Coral, not a bivalve | D11: Bivalve: temperature & pH
A12: 10.1016/j.marpolbul.2024.116454 | B12: Noise pollution causes parental stress on marine invertebrates, the Giant scallop example. | C12: Bivalve but the conditioning stressor is anthropogenic noise, not temperature or pH - outside this scope assignment | D12: Bivalve: temperature & pH
... A132: 10.1186/s12915-020-00811-6 | B132: Paternal hypoxia exposure primes offspring for increased hypoxia resistance (zebrafish) | C132: Vertebrate (zebrafish, freshwater) - fails the marine invertebrate inclusion criterion; DOI not independently verified in Scite | D132: Hypoxia / salinity / pollutant / other taxa
